<?xml version="1.0"?>
<!-- specify to use the xacro in xml namespace  -->
<robot name="rover" xmlns:xacro="http://www.ros.org/wiki/xacro">

    <!-- common-xacro-params -->
    <xacro:property name="length" value="0.8" />
    <xacro:property name="breadth" value="0.4" />
    <xacro:property name="height" value="0.1" />
    <xacro:property name="wheel_radius" value="0.1" />
    <xacro:property name="wheel_length" value="0.05" />
    <xacro:property name="base_mass" value="5.0" />

    <!-- materials -->
    <xacro:macro name="material" params="name color">
        <material name="${name}">
            <color rgba="${color}" />
        </material>
    </xacro:macro>

    <xacro:material name="black" color="0.0 0.0 0.0 1.0" />
    <xacro:material name="white" color="1.0 1.0 1.0 1.0" />

    <!-- wheel-macro -->
    <xacro:macro name="wheel" params="wheel_position reflect_x reflect_y parent">
        <link name="${wheel_position}_wheel">
            <visual>
                <geometry>
                    <cylinder radius="${wheel_radius}" length="${wheel_length}" />
                </geometry>
                <origin xyz="0.0 0.0 0.0" rpy="1.573 0.0 0.0" />
                <material name="black" />
            </visual>
            <collision>
                <geometry>
                    <cylinder radius="${wheel_radius}" length="${wheel_length}" />
                </geometry>
                <origin xyz="0.0 0.0 0.0" rpy="1.573 0.0 0.0" />
            </collision>
        </link>
        <joint name="base_${wheel_position}_wheel" type="continuous">
            <origin
                xyz="${reflect_x * (length / 4)} ${reflect_y * (breadth / 2 + wheel_length / 2)} 0.0"
                rpy="0.0 0.0 0.0" />
            <parent link="${parent}" />
            <child link="${wheel_position}_wheel" />
            <axis xyz="0.0 1.0 0.0" />
        </joint>
    </xacro:macro>

    <!-- footprint -->
    <link name="robot_footprint" />

    <!-- base-link -->
    <link name="base_link">
        <visual>
            <geometry>
                <box size="${length} ${breadth} ${height}" />
            </geometry>
            <material name="white" />
        </visual>
        <collision>
            <geometry>
                <box size="${length} ${breadth} ${height}" />
            </geometry>
        </collision>
        <inertial>
            <mass value="${base_mass}" />
            <inertia ixx="0.0" ixy="0.0" ixz="0.0" iyy="0.0" iyz="0.0" izz="0.0" />
        </inertial>
    </link>

    <!-- base-joint -->
    <joint name="base_joint" type="fixed">
        <parent link="robot_footprint" />
        <child link="base_link" />
        <origin xyz="0.0 0.0 0.1" rpy="0.0 0.0 0.0" />
    </joint>

    <!-- wheels -->
    <xacro:wheel wheel_position="left_front" reflect_x="1.0" reflect_y="1.0" parent="base_link" />
    <xacro:wheel wheel_position="right_front" reflect_x="1.0" reflect_y="-1.0" parent="base_link" />
    <xacro:wheel wheel_position="left_back" reflect_x="-1.0" reflect_y="1.0" parent="base_link" />
    <xacro:wheel wheel_position="right_back" reflect_x="-1.0" reflect_y="-1.0" parent="base_link" />

</robot>